2020-05-03 11:31:04,683 -  nornir.core -     INFO -        run() - Running task 'napalm_get' with args {'getters': ['get_facts']} on 6 hosts
2020-05-03 11:31:04,746 - nornir.core.task -    ERROR -      start() - Host 'SW-3': task 'napalm_get' failed with traceback:
Traceback (most recent call last):
  File "C:\Python38\lib\site-packages\nornir\core\task.py", line 85, in start
    r = self.task(self, **self.params)
  File "C:\Python38\lib\site-packages\nornir\plugins\tasks\networking\napalm_get.py", line 49, in napalm_get
    device = task.host.get_connection("napalm", task.nornir.config)
  File "C:\Python38\lib\site-packages\nornir\core\inventory.py", line 294, in get_connection
    self.open_connection(
  File "C:\Python38\lib\site-packages\nornir\core\inventory.py", line 345, in open_connection
    self.connections[connection].open(
  File "C:\Python38\lib\site-packages\nornir\plugins\connections\napalm.py", line 49, in open
    network_driver = get_network_driver(platform)
  File "C:\Python38\lib\site-packages\napalm\base\__init__.py", line 74, in get_network_driver
    raise ModuleImportError("Please provide a valid driver name.")
napalm.base.exceptions.ModuleImportError: Please provide a valid driver name.

2020-05-03 11:31:04,746 - nornir.core.task -    ERROR -      start() - Host 'SW-6': task 'napalm_get' failed with traceback:
Traceback (most recent call last):
  File "C:\Python38\lib\site-packages\nornir\core\task.py", line 85, in start
    r = self.task(self, **self.params)
  File "C:\Python38\lib\site-packages\nornir\plugins\tasks\networking\napalm_get.py", line 49, in napalm_get
    device = task.host.get_connection("napalm", task.nornir.config)
  File "C:\Python38\lib\site-packages\nornir\core\inventory.py", line 294, in get_connection
    self.open_connection(
  File "C:\Python38\lib\site-packages\nornir\core\inventory.py", line 345, in open_connection
    self.connections[connection].open(
  File "C:\Python38\lib\site-packages\nornir\plugins\connections\napalm.py", line 49, in open
    network_driver = get_network_driver(platform)
  File "C:\Python38\lib\site-packages\napalm\base\__init__.py", line 74, in get_network_driver
    raise ModuleImportError("Please provide a valid driver name.")
napalm.base.exceptions.ModuleImportError: Please provide a valid driver name.

2020-05-03 11:31:04,746 - nornir.core.task -    ERROR -      start() - Host 'SW-2': task 'napalm_get' failed with traceback:
Traceback (most recent call last):
  File "C:\Python38\lib\site-packages\nornir\core\task.py", line 85, in start
    r = self.task(self, **self.params)
  File "C:\Python38\lib\site-packages\nornir\plugins\tasks\networking\napalm_get.py", line 49, in napalm_get
    device = task.host.get_connection("napalm", task.nornir.config)
  File "C:\Python38\lib\site-packages\nornir\core\inventory.py", line 294, in get_connection
    self.open_connection(
  File "C:\Python38\lib\site-packages\nornir\core\inventory.py", line 345, in open_connection
    self.connections[connection].open(
  File "C:\Python38\lib\site-packages\nornir\plugins\connections\napalm.py", line 49, in open
    network_driver = get_network_driver(platform)
  File "C:\Python38\lib\site-packages\napalm\base\__init__.py", line 74, in get_network_driver
    raise ModuleImportError("Please provide a valid driver name.")
napalm.base.exceptions.ModuleImportError: Please provide a valid driver name.

2020-05-03 11:31:04,746 - nornir.core.task -    ERROR -      start() - Host 'SW-1': task 'napalm_get' failed with traceback:
Traceback (most recent call last):
  File "C:\Python38\lib\site-packages\nornir\core\task.py", line 85, in start
    r = self.task(self, **self.params)
  File "C:\Python38\lib\site-packages\nornir\plugins\tasks\networking\napalm_get.py", line 49, in napalm_get
    device = task.host.get_connection("napalm", task.nornir.config)
  File "C:\Python38\lib\site-packages\nornir\core\inventory.py", line 294, in get_connection
    self.open_connection(
  File "C:\Python38\lib\site-packages\nornir\core\inventory.py", line 345, in open_connection
    self.connections[connection].open(
  File "C:\Python38\lib\site-packages\nornir\plugins\connections\napalm.py", line 49, in open
    network_driver = get_network_driver(platform)
  File "C:\Python38\lib\site-packages\napalm\base\__init__.py", line 74, in get_network_driver
    raise ModuleImportError("Please provide a valid driver name.")
napalm.base.exceptions.ModuleImportError: Please provide a valid driver name.

2020-05-03 11:31:04,762 - nornir.core.task -    ERROR -      start() - Host 'SW-5': task 'napalm_get' failed with traceback:
Traceback (most recent call last):
  File "C:\Python38\lib\site-packages\nornir\core\task.py", line 85, in start
    r = self.task(self, **self.params)
  File "C:\Python38\lib\site-packages\nornir\plugins\tasks\networking\napalm_get.py", line 49, in napalm_get
    device = task.host.get_connection("napalm", task.nornir.config)
  File "C:\Python38\lib\site-packages\nornir\core\inventory.py", line 294, in get_connection
    self.open_connection(
  File "C:\Python38\lib\site-packages\nornir\core\inventory.py", line 345, in open_connection
    self.connections[connection].open(
  File "C:\Python38\lib\site-packages\nornir\plugins\connections\napalm.py", line 49, in open
    network_driver = get_network_driver(platform)
  File "C:\Python38\lib\site-packages\napalm\base\__init__.py", line 74, in get_network_driver
    raise ModuleImportError("Please provide a valid driver name.")
napalm.base.exceptions.ModuleImportError: Please provide a valid driver name.

2020-05-03 11:31:04,762 - nornir.core.task -    ERROR -      start() - Host 'SW-4': task 'napalm_get' failed with traceback:
Traceback (most recent call last):
  File "C:\Python38\lib\site-packages\nornir\core\task.py", line 85, in start
    r = self.task(self, **self.params)
  File "C:\Python38\lib\site-packages\nornir\plugins\tasks\networking\napalm_get.py", line 49, in napalm_get
    device = task.host.get_connection("napalm", task.nornir.config)
  File "C:\Python38\lib\site-packages\nornir\core\inventory.py", line 294, in get_connection
    self.open_connection(
  File "C:\Python38\lib\site-packages\nornir\core\inventory.py", line 345, in open_connection
    self.connections[connection].open(
  File "C:\Python38\lib\site-packages\nornir\plugins\connections\napalm.py", line 49, in open
    network_driver = get_network_driver(platform)
  File "C:\Python38\lib\site-packages\napalm\base\__init__.py", line 74, in get_network_driver
    raise ModuleImportError("Please provide a valid driver name.")
napalm.base.exceptions.ModuleImportError: Please provide a valid driver name.
